<?xml version="1.0" encoding="utf-8"?>
<robot name="robot_display">
  <link name="body"/>

  <joint name="body_to_base_footprint_joint" type="fixed">
    <parent link="body" />
    <child link="base_footprint" />
    <origin xyz="0.274505096 -0.023340782 -0.811089435" rpy="0.0000583155 -0.3490658504 -0.000170503" />
  </joint>

  <link name="base_footprint"/>
  
  <link name="base_link">
    <inertial>
      <origin xyz="-0.0098325143429585 -5.2540282666803E-05 0.392384583771952" rpy="0 0 0" />
      <mass value="1.52093247375048" />
      <inertia
        ixx="0.0176542350747674"
        ixy="-3.064862511353E-08"
        ixz="2.89095999810399E-05"
        iyy="0.0170775483739283"
        iyz="-6.04177568974473E-08"
        izz="0.00135407024623668" />
    </inertial>
    <visual>
      <origin xyz="0 0 0" rpy="0 0 0" />
      <geometry>
        <mesh filename="package://robot_display/meshes/base_link.STL" />
      </geometry>
      <material name="">
        <color rgba="1.0 1.0 1.0 1" />
      </material>
    </visual>
    <collision>
      <origin xyz="0 0 0" rpy="0 0 0" />
      <geometry>
        <mesh filename="package://robot_display/meshes/base_link.STL" />
      </geometry>
    </collision>
  </link>

  <joint name="base_footprint_joint" type="fixed">
    <parent link="base_footprint"/>
    <child link="base_link"/>
    <origin xyz="0 0 0.0105" rpy="0 0 0"/>
  </joint>

  <link name="whell_left_link">
    <inertial>
      <origin xyz="-7.85437210621548E-07 0.00048137342557214 1.11756020021447E-06" rpy="0 0 0" />
      <mass value="0.315479735385035" />
      <inertia
        ixx="0.000221117820208823"
        ixy="3.5833843868722E-10"
        ixz="-6.72123977051372E-09"
        iyy="0.000357084383299597"
        iyz="1.4251993170265E-08"
        izz="0.000221134649609164" />
    </inertial>
    <visual>
      <origin xyz="0 0 0" rpy="0 0 0" />
      <geometry>
        <mesh filename="package://robot_display/meshes/whell_left_link.STL" />
      </geometry>
      <material name="">
        <color rgba="0.2 1 0.2 1" />
      </material>
    </visual>
    <collision>
      <origin xyz="0 0 0" rpy="0 0 0" />
      <geometry>
        <mesh filename="package://robot_display/meshes/whell_left_link.STL" />
      </geometry>
    </collision>
  </link>

  <joint name="whell_left_joint" type="continuous">
    <origin xyz="0 0.188 0.04" rpy="0 0 0" />
    <parent link="base_link" />
    <child link="whell_left_link" />
    <axis xyz="0 1 0" />
  </joint>

  <link name="wheel_right_link">
    <inertial>
      <origin xyz="7.85441963985917E-07 -0.000481373418943581 1.11756507803484E-06" rpy="0 0 0" />
      <mass value="0.315479735504946" />
      <inertia
        ixx="0.000221117820259764"
        ixy="3.58314078627961E-10"
        ixz="6.72121924957937E-09"
        iyy="0.000357084383339721"
        iyz="-1.42520181537281E-08"
        izz="0.000221134649658052" />
    </inertial>
    <visual>
      <origin xyz="0 0 0" rpy="0 0 0" />
      <geometry>
        <mesh filename="package://robot_display/meshes/wheel_right_link.STL" />
      </geometry>
      <material name="">
        <color rgba="0.2 1 0.2 1" />
      </material>
    </visual>
    <collision>
      <origin xyz="0 0 0" rpy="0 0 0" />
      <geometry>
        <mesh filename="package://robot_display/meshes/wheel_right_link.STL" />
      </geometry>
    </collision>
  </link>

  <joint name="wheel_right_joint" type="continuous">
    <origin xyz="0 -0.188 0.04" rpy="0 0 0" />
    <parent link="base_link" />
    <child link="wheel_right_link" />
    <axis xyz="0 1 0" />
  </joint>

  <link name="screw_link">
    <inertial>
      <origin xyz="-0.00769620815871298 3.50362013748799E-06 0.0288829961541191" rpy="0 0 0" />
      <mass value="0.477619946924312" />
      <inertia
        ixx="0.00325280225415715"
        ixy="3.30969826037761E-09"
        ixz="-2.28880534043066E-06"
        iyy="0.000831911086109197"
        iyz="-3.29348610207974E-09"
        izz="0.00264549391304978" />
    </inertial>
    <visual>
      <origin xyz="0 0 0" rpy="0 0 0" />
      <geometry>
        <mesh filename="package://robot_display/meshes/screw_link.STL" />
      </geometry>
      <material name="">
        <color rgba="1 0.5 0 1" />
      </material>
    </visual>
    <collision>
      <origin xyz="0 0 0" rpy="0 0 0" />
      <geometry>
        <mesh filename="package://robot_display/meshes/screw_link.STL" />
      </geometry>
    </collision>
  </link>

  <joint name="screw_joint" type="prismatic">
    <origin xyz="0.0616483321125747 5.00000000000496E-05 0.671" rpy="0 0 0" />
    <parent link="base_link" />
    <child link="screw_link" />
    <axis xyz="0 0 -1" />
    <limit lower="-0.2" upper="0" effort="100" velocity="0.1" />
  </joint>

  <link name="camera_poo_link">
    <inertial>
      <origin xyz="0.0141559028046791 -0.0470107561831965 -0.000119325004315163" rpy="0 0 0" />
      <mass value="0.0326390241085313" />
      <inertia
        ixx="4.07693585659203E-05"
        ixy="2.08779440174718E-07"
        ixz="-8.11014549496065E-08"
        iyy="4.42525295935665E-06"
        iyz="2.25017432153555E-07"
        izz="4.01659365922531E-05" />
    </inertial>
    <visual>
      <origin xyz="0 0 0" rpy="0 0 0" />
      <geometry>
        <mesh filename="package://robot_display/meshes/camera_link.STL" />
      </geometry>
      <material name="">
        <color rgba="1 1 0 1" />
      </material>
    </visual>
    <collision>
      <origin xyz="0 0 0" rpy="0 0 0" />
      <geometry>
        <mesh filename="package://robot_display/meshes/camera_link.STL" />
      </geometry>
    </collision>
  </link>

  <joint name="camera_joint" type="fixed">
    <origin xyz="0.0336516678874285 0.0474500000000005 0.324490381056767" rpy="0 0.5235987755983 0" />
    <parent link="screw_link" />
    <child link="camera_poo_link" />
  </joint>

  <link name="camera_link"/>

  <joint name="camera_poo_to_camera_joint" type="fixed">
    <parent link="camera_poo_link" />
    <child link="camera_link" />
    <origin xyz="0.02292 0 0" rpy="0 0 0" />
  </joint>

  <link name="livox_poo_link">
    <inertial>
      <origin xyz="-0.0011535215104774 -1.68497683204461E-05 0.0041860206540324" rpy="0 0 0" />
      <mass value="0.0525930263369941" />
      <inertia
        ixx="1.13650314609516E-05"
        ixy="-5.6844398475156E-09"
        ixz="5.26601377270881E-10"
        iyy="1.13966414073652E-05"
        iyz="-6.4096263936136E-10"
        izz="1.91792981689664E-05" />
    </inertial>
    <visual>
      <origin xyz="0 0 0" rpy="0 0 0" />
      <geometry>
        <mesh filename="package://robot_display/meshes/livox_link.STL" />
      </geometry>
      <material name="">
        <color rgba="0 0.2 0.8 1" />
      </material>
    </visual>
    <collision>
      <origin xyz="0 0 0" rpy="0 0 0" />
      <geometry>
        <mesh filename="package://robot_display/meshes/livox_link.STL" />
      </geometry>
    </collision>
  </link>

  <joint name="livox_joint" type="fixed">
    <origin xyz="0.0170020182229269 5.3506078218414E-05 0.87097369906952" rpy="0 0.349065850398866 0.000160221167896802" />
    <parent link="base_link" />
    <child link="livox_poo_link" />
  </joint>

  <link name="livox_frame"/>

  <joint name="livox_poo_to_livox_joint" type="fixed">
    <parent link="livox_poo_link" />
    <child link="livox_frame" />
    <origin xyz="0 0 0.02108" rpy="0 0 0" />
  </joint>

</robot>